[2022-07-16 13:06:01,178] {taskinstance.py:1179} INFO - Dependencies all met for <TaskInstance: car_price_prediction.predict manual__2022-07-16T13:05:46.835256+00:00 [queued]>
[2022-07-16 13:06:01,218] {taskinstance.py:1179} INFO - Dependencies all met for <TaskInstance: car_price_prediction.predict manual__2022-07-16T13:05:46.835256+00:00 [queued]>
[2022-07-16 13:06:01,239] {taskinstance.py:1376} INFO - 
--------------------------------------------------------------------------------
[2022-07-16 13:06:01,244] {taskinstance.py:1377} INFO - Starting attempt 1 of 2
[2022-07-16 13:06:01,246] {taskinstance.py:1378} INFO - 
--------------------------------------------------------------------------------
[2022-07-16 13:06:01,314] {taskinstance.py:1397} INFO - Executing <Task(PythonOperator): predict> on 2022-07-16 13:05:46.835256+00:00
[2022-07-16 13:06:01,377] {standard_task_runner.py:52} INFO - Started process 3937 to run task
[2022-07-16 13:06:01,394] {standard_task_runner.py:79} INFO - Running: ['***', 'tasks', 'run', 'car_price_prediction', 'predict', 'manual__2022-07-16T13:05:46.835256+00:00', '--job-id', '61', '--raw', '--subdir', 'DAGS_FOLDER/hw_dag.py', '--cfg-path', '/tmp/tmptipaw1y0', '--error-file', '/tmp/tmps81gy0r4']
[2022-07-16 13:06:01,430] {standard_task_runner.py:80} INFO - Job 61: Subtask predict
[2022-07-16 13:06:01,851] {task_command.py:371} INFO - Running <TaskInstance: car_price_prediction.predict manual__2022-07-16T13:05:46.835256+00:00 [running]> on host 744d078d7eff
[2022-07-16 13:06:02,076] {taskinstance.py:1591} INFO - Exporting the following env vars:
AIRFLOW_CTX_DAG_OWNER=***
AIRFLOW_CTX_DAG_ID=car_price_prediction
AIRFLOW_CTX_TASK_ID=predict
AIRFLOW_CTX_EXECUTION_DATE=2022-07-16T13:05:46.835256+00:00
AIRFLOW_CTX_TRY_NUMBER=1
AIRFLOW_CTX_DAG_RUN_ID=manual__2022-07-16T13:05:46.835256+00:00
[2022-07-16 13:06:02,112] {taskinstance.py:1909} ERROR - Task failed with exception
Traceback (most recent call last):
  File "/home/airflow/.local/lib/python3.7/site-packages/airflow/operators/python.py", line 171, in execute
    return_value = self.execute_callable()
  File "/home/airflow/.local/lib/python3.7/site-packages/airflow/operators/python.py", line 189, in execute_callable
    return self.python_callable(*self.op_args, **self.op_kwargs)
  File "/opt/airflow/dags/modules/predict.py", line 25, in predict
    test_data = get_raw_test_data()
  File "/opt/airflow/dags/modules/predict.py", line 14, in get_raw_test_data
    for filename in os.listdir(test_dir):
FileNotFoundError: [Errno 2] No such file or directory: '/opt/airflow/dags/data/test/'
[2022-07-16 13:06:02,141] {taskinstance.py:1420} INFO - Marking task as UP_FOR_RETRY. dag_id=car_price_prediction, task_id=predict, execution_date=20220716T130546, start_date=20220716T130601, end_date=20220716T130602
[2022-07-16 13:06:02,168] {standard_task_runner.py:97} ERROR - Failed to execute job 61 for task predict ([Errno 2] No such file or directory: '/opt/airflow/dags/data/test/'; 3937)
[2022-07-16 13:06:02,237] {local_task_job.py:156} INFO - Task exited with return code 1
[2022-07-16 13:06:02,314] {local_task_job.py:273} INFO - 0 downstream tasks scheduled from follow-on schedule check
